<?xml version="1.0" encoding="utf-8" standalone="yes"?><rss version="2.0" xmlns:atom="http://www.w3.org/2005/Atom"><channel><title>exception handling on Michael J. Nicholson</title><link>https://michjnich.github.io/tags/exception-handling/</link><description>Recent content in exception handling on Michael J. Nicholson</description><generator>Hugo -- gohugo.io</generator><language>en-gb</language><lastBuildDate>Tue, 21 Mar 2023 11:00:00 +0100</lastBuildDate><atom:link href="https://michjnich.github.io/tags/exception-handling/index.xml" rel="self" type="application/rss+xml"/><item><title>try...except...else...finally</title><link>https://michjnich.github.io/posts/tech/2023/try-except-else-finally/</link><pubDate>Tue, 21 Mar 2023 11:00:00 +0100</pubDate><guid>https://michjnich.github.io/posts/tech/2023/try-except-else-finally/</guid><description>Like many languages, Python provides functionality for catching errors using a try...except block. Java, for example, has try...catch which operates in a similar way, but Python goes beyond other languages by providing extra blocks.
Basic exception handling Let&amp;rsquo;s have a quick run through how exception catching works in Python.
x = 0 # x = 10 try: y = 100 / x except ZeroDivisionError: y = 0 except Exception as e: print(e) This is your standard try.</description></item></channel></rss>